Traceback (most recent call last):
  File "/Library/Frameworks/Python.framework/Versions/3.6/lib/python3.6/site-packages/nbclient/client.py", line 609, in _async_poll_for_reply
    msg = await ensure_async(self.kc.shell_channel.get_msg(timeout=new_timeout))
  File "/Library/Frameworks/Python.framework/Versions/3.6/lib/python3.6/site-packages/nbclient/util.py", line 85, in ensure_async
    result = await obj
  File "/Library/Frameworks/Python.framework/Versions/3.6/lib/python3.6/site-packages/jupyter_client/asynchronous/channels.py", line 48, in get_msg
    raise Empty
queue.Empty

During handling of the above exception, another exception occurred:

Traceback (most recent call last):
  File "/Library/Frameworks/Python.framework/Versions/3.6/lib/python3.6/site-packages/jupyter_cache/executors/utils.py", line 56, in single_nb_execution
    record_timing=False,
  File "/Library/Frameworks/Python.framework/Versions/3.6/lib/python3.6/site-packages/nbclient/client.py", line 1087, in execute
    return NotebookClient(nb=nb, resources=resources, km=km, **kwargs).execute()
  File "/Library/Frameworks/Python.framework/Versions/3.6/lib/python3.6/site-packages/nbclient/util.py", line 74, in wrapped
    return just_run(coro(*args, **kwargs))
  File "/Library/Frameworks/Python.framework/Versions/3.6/lib/python3.6/site-packages/nbclient/util.py", line 53, in just_run
    return loop.run_until_complete(coro)
  File "/Library/Frameworks/Python.framework/Versions/3.6/lib/python3.6/asyncio/base_events.py", line 484, in run_until_complete
    return future.result()
  File "/Library/Frameworks/Python.framework/Versions/3.6/lib/python3.6/site-packages/nbclient/client.py", line 541, in async_execute
    cell, index, execution_count=self.code_cells_executed + 1
  File "/Library/Frameworks/Python.framework/Versions/3.6/lib/python3.6/site-packages/nbclient/client.py", line 816, in async_execute_cell
    exec_reply = await self.task_poll_for_reply
  File "/Library/Frameworks/Python.framework/Versions/3.6/lib/python3.6/site-packages/nbclient/client.py", line 633, in _async_poll_for_reply
    await self._async_handle_timeout(timeout, cell)
  File "/Library/Frameworks/Python.framework/Versions/3.6/lib/python3.6/site-packages/nbclient/client.py", line 684, in _async_handle_timeout
    "Cell execution timed out", timeout, cell
nbclient.exceptions.CellTimeoutError: A cell timed out while it was being executed, after 30 seconds.
The message was: Cell execution timed out.
Here is a preview of the cell contents:
-------------------
with model_1:
    obs_A = pm.StudentT("obs_A", mu = mu_A, lam = 1.0/std_A**2, nu = nu_minus_1+1, observed = Control_Matrix.Pvs_per_session)
    obs_B = pm.StudentT("obs_B", mu = mu_B, lam = 1.0/std_B**2, nu = nu_minus_1+1, observed = Variant_BT.Pvs_per_session)
    start = pm.find_MAP()
    step = pm.Metropolis(vars=[mu_A, mu_B, std_A, std_B, nu_minus_1])
    trace_1 = pm.sample(25000, step=step)
    burned_trace_1 = trace_1[10000:]
-------------------

